<?xml version="1.0" ?>
<!-- =================================================================================== -->
<!-- |    This document was autogenerated by xacro from urdf/robot.xacro               | -->
<!-- |    EDITING THIS FILE BY HAND IS NOT RECOMMENDED                                 | -->
<!-- =================================================================================== -->
<robot name="robot">
  <material name="black">
    <color rgba="0.0 0.0 0.0 1.0"/>
  </material>
  <material name="blue">
    <color rgba="0.0 0.0 0.8 1.0"/>
  </material>
  <material name="green">
    <color rgba="0.0 0.8 0.0 1.0"/>
  </material>
  <material name="grey">
    <color rgba="0.2 0.2 0.2 1.0"/>
  </material>
  <material name="silver">
    <color rgba="0.9137254901960784 0.9137254901960784 0.8470588235294118 1.0"/>
  </material>
  <material name="orange">
    <color rgba="1.0 0.4235294117647059 0.0392156862745098 1.0"/>
  </material>
  <material name="brown">
    <color rgba="0.8705882352941177 0.8117647058823529 0.7647058823529411 1.0"/>
  </material>
  <material name="red">
    <color rgba="0.8 0.0 0.0 1.0"/>
  </material>
  <material name="white">
    <color rgba="1.0 1.0 1.0 1.0"/>
  </material>
  <!-- ros_control plugin -->
  <gazebo>
    <plugin filename="liblegged_hw_sim.so" name="gazebo_ros_control">
      <robotNamespace>/</robotNamespace>
      <robotParam>legged_robot_description</robotParam>
      <robotSimType>legged_gazebo/LeggedHWSim</robotSimType>
    </plugin>
  </gazebo>
  <gazebo>
    <plugin filename="libgazebo_ros_p3d.so" name="p3d_base_controller">
      <alwaysOn>true</alwaysOn>
      <updateRate>1000.0</updateRate>
      <bodyName>base</bodyName>
      <topicName>ground_truth/state</topicName>
      <gaussianNoise>0</gaussianNoise>
      <frameName>world</frameName>
      <xyzOffsets>0 0 0</xyzOffsets>
      <rpyOffsets>0 0 0</rpyOffsets>
    </plugin>
  </gazebo>
  <link name="base">
    <visual>
      <origin rpy="0 0 0" xyz="0 0 0"/>
      <geometry>
        <mesh filename="package://Arm_URDF/meshes/go1/trunk.dae" scale="1 1 1"/>
      </geometry>
    </visual>
    <collision>
      <origin rpy="0 0 0" xyz="0 0 0"/>
      <geometry>
        <box size="0.3762 0.0935 0.114"/>
      </geometry>
    </collision>
    <inertial>
      <origin rpy="0 0 0" xyz="0.0223 0.002 -0.0005"/>
      <mass value="5.204"/>
      <inertia ixx="0.0168128557" ixy="-0.0002296769" ixz="-0.0002945293" iyy="0.063009565" iyz="-4.18731e-05" izz="0.0716547275"/>
    </inertial>
  </link>
  <!-- Imu is fixed to the base link -->
  <joint name="unitree_imu_joint" type="fixed">
    <origin rpy="0. 0. 0." xyz="0. 0. 0."/>
    <parent link="base"/>
    <child link="unitree_imu"/>
  </joint>
  <!-- Imu link -->
  <link name="unitree_imu">
    <inertial>
      <mass value="0.01"/>
      <origin rpy="0 0 0" xyz="0 0 0"/>
      <inertia ixx="0.000001" ixy="0" ixz="0" iyy="0.000001" iyz="0" izz="0.000001"/>
    </inertial>
    <visual>
      <origin rpy="0 0 0" xyz="0 0 0"/>
      <geometry>
        <box size="0.015 0.015 0.004"/>
      </geometry>
    </visual>
    <material name="orange">
      <color rgba="255 108 10 255"/>
    </material>
  </link>
  <gazebo reference="unitree_imu">
    <material>Gazebo/Orange</material>
  </gazebo>
  <gazebo reference="unitree_imu_joint">
    <disableFixedJointLumping>true</disableFixedJointLumping>
  </gazebo>
  <joint name="RF_HAA" type="revolute">
    <origin rpy="0 0 0" xyz="0.1881 -0.04675 0"/>
    <parent link="base"/>
    <child link="RF_hip"/>
    <axis xyz="1 0 0"/>
    <dynamics damping="0.01" friction="0.2"/>
    <limit effort="23.7" lower="-0.863" upper="0.863" velocity="30.1"/>
  </joint>
  <link name="RF_hip">
    <visual>
      <origin rpy="3.141592653589793 0 0" xyz="0 0 0"/>
      <geometry>
        <mesh filename="package://Arm_URDF/meshes/go1/hip.dae" scale="1 1 1"/>
      </geometry>
      <material name="orange"/>
    </visual>
    <collision>
      <origin rpy="1.5707963267948966 0 0" xyz="0 0 0"/>
      <geometry>
        <cylinder length="0.04" radius="0.046"/>
      </geometry>
    </collision>
    <inertial>
      <origin rpy="0 0 0" xyz="-0.005657 0.008752 -0.000102"/>
      <mass value="0.591"/>
      <inertia ixx="0.000334008405" ixy="1.0826066e-05" ixz="1.290732e-06" iyy="0.000619101213" iyz="-1.643194e-06" izz="0.00040057614"/>
    </inertial>
  </link>
  <joint name="RF_HFE" type="revolute">
    <origin rpy="0 0 0" xyz="0 -0.08 0"/>
    <parent link="RF_hip"/>
    <child link="RF_thigh"/>
    <axis xyz="0 1 0"/>
    <dynamics damping="0.01" friction="0.2"/>
    <limit effort="23.7" lower="-0.686" upper="4.501" velocity="30.1"/>
  </joint>
  <link name="RF_thigh">
    <visual>
      <origin rpy="0 0 0" xyz="0 0 0"/>
      <geometry>
        <mesh filename="package://Arm_URDF/meshes/go1/thigh_mirror.dae" scale="1 1 1"/>
      </geometry>
      <material name="orange"/>
    </visual>
    <collision>
      <origin rpy="0 1.6707963267948966 0" xyz="-0.015 0 -0.1065"/>
      <geometry>
        <box size="0.213 0.0245 0.034"/>
      </geometry>
    </collision>
    <collision>
      <origin rpy="1.5707963267948966 0 0" xyz="0 0.008 0"/>
      <geometry>
        <cylinder length="0.032" radius="0.041"/>
      </geometry>
    </collision>
    <inertial>
      <origin rpy="0 0 0" xyz="-0.003342 0.018054 -0.033451"/>
      <mass value="0.92"/>
      <inertia ixx="0.004431760472" ixy="-5.7496807e-05" ixz="-0.000218457134" iyy="0.004485671726" iyz="-0.000572001265" izz="0.000740309489"/>
    </inertial>
  </link>
  <joint name="RF_KFE" type="revolute">
    <origin rpy="0 0 0" xyz="0 0 -0.213"/>
    <parent link="RF_thigh"/>
    <child link="RF_calf"/>
    <axis xyz="0 1 0"/>
    <dynamics damping="0.01" friction="0.2"/>
    <limit effort="35.55" lower="-2.818" upper="-0.888" velocity="20.06"/>
  </joint>
  <link name="RF_calf">
    <visual>
      <origin rpy="0 0 0" xyz="0 0 0"/>
      <geometry>
        <mesh filename="package://Arm_URDF/meshes/go1/calf.dae" scale="1 1 1"/>
      </geometry>
      <material name="orange"/>
    </visual>
    <collision>
      <origin rpy="0 1.5707963267948966 0" xyz="0.0 0 -0.1065"/>
      <geometry>
        <box size="0.213 0.016 0.016"/>
      </geometry>
    </collision>
    <inertial>
      <origin rpy="0 0 0" xyz="0.006197 0.001408 -0.116695"/>
      <mass value="0.135862"/>
      <inertia ixx="0.001088793059" ixy="-2.55679e-07" ixz="7.117814e-06" iyy="0.001100428748" iyz="2.077264e-06" izz="2.4787446e-05"/>
    </inertial>
  </link>
  <joint name="RF_foot_fixed" type="fixed">
    <origin rpy="0 0 0" xyz="0 0 -0.213"/>
    <parent link="RF_calf"/>
    <child link="RF_FOOT"/>
  </joint>
  <link name="RF_FOOT">
    <visual>
      <origin rpy="0 0 0" xyz="0 0 0"/>
      <geometry>
        <sphere radius="0.01"/>
      </geometry>
      <material name="orange"/>
    </visual>
    <collision>
      <origin rpy="0 0 0" xyz="0 0 0"/>
      <geometry>
        <sphere radius="0.02"/>
      </geometry>
    </collision>
    <inertial>
      <mass value="0.06"/>
      <inertia ixx="9.600000000000001e-06" ixy="0.0" ixz="0.0" iyy="9.600000000000001e-06" iyz="0.0" izz="9.600000000000001e-06"/>
    </inertial>
  </link>
  <gazebo reference="RF_foot_fixed">
    <disableFixedJointLumping>true</disableFixedJointLumping>
  </gazebo>
  <gazebo reference="RF_hip">
    <mu1>0.2</mu1>
    <mu2>0.2</mu2>
    <material>Gazebo/DarkGrey</material>
  </gazebo>
  <gazebo reference="RF_thigh">
    <mu1>0.2</mu1>
    <mu2>0.2</mu2>
    <self_collide>0</self_collide>
    <material>Gazebo/DarkGrey</material>
    <kp value="1000000.0"/>
    <kd value="100.0"/>
  </gazebo>
  <gazebo reference="RF_calf">
    <mu1>0.6</mu1>
    <mu2>0.6</mu2>
    <self_collide>1</self_collide>
  </gazebo>
  <gazebo reference="RF_FOOT">
    <mu1>0.6</mu1>
    <mu2>0.6</mu2>
    <self_collide>1</self_collide>
    <material>Gazebo/DarkGrey</material>
    <kp value="1000000.0"/>
    <kd value="100.0"/>
  </gazebo>
  <transmission name="RF_HAA_tran">
    <type>transmission_interface/SimpleTransmission</type>
    <joint name="RF_HAA">
      <hardwareInterface>hardware_interface/EffortJointInterface</hardwareInterface>
    </joint>
    <actuator name="RF_HAA_motor">
      <hardwareInterface>hardware_interface/EffortJointInterface</hardwareInterface>
      <mechanicalReduction>1</mechanicalReduction>
    </actuator>
  </transmission>
  <transmission name="RF_HFE_tran">
    <type>transmission_interface/SimpleTransmission</type>
    <joint name="RF_HFE">
      <hardwareInterface>hardware_interface/EffortJointInterface</hardwareInterface>
    </joint>
    <actuator name="RF_HFE_motor">
      <hardwareInterface>hardware_interface/EffortJointInterface</hardwareInterface>
      <mechanicalReduction>1</mechanicalReduction>
    </actuator>
  </transmission>
  <transmission name="RF_KFE_tran">
    <type>transmission_interface/SimpleTransmission</type>
    <joint name="RF_KFE">
      <hardwareInterface>hardware_interface/EffortJointInterface</hardwareInterface>
    </joint>
    <actuator name="RF_KFE_motor">
      <hardwareInterface>hardware_interface/EffortJointInterface</hardwareInterface>
      <mechanicalReduction>1</mechanicalReduction>
    </actuator>
  </transmission>
  <joint name="LF_HAA" type="revolute">
    <origin rpy="0 0 0" xyz="0.1881 0.04675 0"/>
    <parent link="base"/>
    <child link="LF_hip"/>
    <axis xyz="1 0 0"/>
    <dynamics damping="0.01" friction="0.2"/>
    <limit effort="23.7" lower="-0.863" upper="0.863" velocity="30.1"/>
  </joint>
  <link name="LF_hip">
    <visual>
      <origin rpy="0 0 0" xyz="0 0 0"/>
      <geometry>
        <mesh filename="package://Arm_URDF/meshes/go1/hip.dae" scale="1 1 1"/>
      </geometry>
      <material name="orange"/>
    </visual>
    <collision>
      <origin rpy="1.5707963267948966 0 0" xyz="0 0 0"/>
      <geometry>
        <cylinder length="0.04" radius="0.046"/>
      </geometry>
    </collision>
    <inertial>
      <origin rpy="0 0 0" xyz="-0.005657 -0.008752 -0.000102"/>
      <mass value="0.591"/>
      <inertia ixx="0.000334008405" ixy="-1.0826066e-05" ixz="1.290732e-06" iyy="0.000619101213" iyz="1.643194e-06" izz="0.00040057614"/>
    </inertial>
  </link>
  <joint name="LF_HFE" type="revolute">
    <origin rpy="0 0 0" xyz="0 0.08 0"/>
    <parent link="LF_hip"/>
    <child link="LF_thigh"/>
    <axis xyz="0 1 0"/>
    <dynamics damping="0.01" friction="0.2"/>
    <limit effort="23.7" lower="-0.686" upper="4.501" velocity="30.1"/>
  </joint>
  <link name="LF_thigh">
    <visual>
      <origin rpy="0 0 0" xyz="0 0 0"/>
      <geometry>
        <mesh filename="package://Arm_URDF/meshes/go1/thigh.dae" scale="1 1 1"/>
      </geometry>
      <material name="orange"/>
    </visual>
    <collision>
      <origin rpy="0 1.6707963267948966 0" xyz="-0.015 0 -0.1065"/>
      <geometry>
        <box size="0.213 0.0245 0.034"/>
      </geometry>
    </collision>
    <collision>
      <origin rpy="1.5707963267948966 0 0" xyz="0 -0.008 0"/>
      <geometry>
        <cylinder length="0.032" radius="0.041"/>
      </geometry>
    </collision>
    <inertial>
      <origin rpy="0 0 0" xyz="-0.003342 -0.018054 -0.033451"/>
      <mass value="0.92"/>
      <inertia ixx="0.004431760472" ixy="5.7496807e-05" ixz="-0.000218457134" iyy="0.004485671726" iyz="0.000572001265" izz="0.000740309489"/>
    </inertial>
  </link>
  <joint name="LF_KFE" type="revolute">
    <origin rpy="0 0 0" xyz="0 0 -0.213"/>
    <parent link="LF_thigh"/>
    <child link="LF_calf"/>
    <axis xyz="0 1 0"/>
    <dynamics damping="0.01" friction="0.2"/>
    <limit effort="35.55" lower="-2.818" upper="-0.888" velocity="20.06"/>
  </joint>
  <link name="LF_calf">
    <visual>
      <origin rpy="0 0 0" xyz="0 0 0"/>
      <geometry>
        <mesh filename="package://Arm_URDF/meshes/go1/calf.dae" scale="1 1 1"/>
      </geometry>
      <material name="orange"/>
    </visual>
    <collision>
      <origin rpy="0 1.5707963267948966 0" xyz="0.0 0 -0.1065"/>
      <geometry>
        <box size="0.213 0.016 0.016"/>
      </geometry>
    </collision>
    <inertial>
      <origin rpy="0 0 0" xyz="0.006197 0.001408 -0.116695"/>
      <mass value="0.135862"/>
      <inertia ixx="0.001088793059" ixy="-2.55679e-07" ixz="7.117814e-06" iyy="0.001100428748" iyz="2.077264e-06" izz="2.4787446e-05"/>
    </inertial>
  </link>
  <joint name="LF_foot_fixed" type="fixed">
    <origin rpy="0 0 0" xyz="0 0 -0.213"/>
    <parent link="LF_calf"/>
    <child link="LF_FOOT"/>
  </joint>
  <link name="LF_FOOT">
    <visual>
      <origin rpy="0 0 0" xyz="0 0 0"/>
      <geometry>
        <sphere radius="0.01"/>
      </geometry>
      <material name="orange"/>
    </visual>
    <collision>
      <origin rpy="0 0 0" xyz="0 0 0"/>
      <geometry>
        <sphere radius="0.02"/>
      </geometry>
    </collision>
    <inertial>
      <mass value="0.06"/>
      <inertia ixx="9.600000000000001e-06" ixy="0.0" ixz="0.0" iyy="9.600000000000001e-06" iyz="0.0" izz="9.600000000000001e-06"/>
    </inertial>
  </link>
  <gazebo reference="LF_foot_fixed">
    <disableFixedJointLumping>true</disableFixedJointLumping>
  </gazebo>
  <gazebo reference="LF_hip">
    <mu1>0.2</mu1>
    <mu2>0.2</mu2>
    <material>Gazebo/DarkGrey</material>
  </gazebo>
  <gazebo reference="LF_thigh">
    <mu1>0.2</mu1>
    <mu2>0.2</mu2>
    <self_collide>0</self_collide>
    <material>Gazebo/DarkGrey</material>
    <kp value="1000000.0"/>
    <kd value="100.0"/>
  </gazebo>
  <gazebo reference="LF_calf">
    <mu1>0.6</mu1>
    <mu2>0.6</mu2>
    <self_collide>1</self_collide>
  </gazebo>
  <gazebo reference="LF_FOOT">
    <mu1>0.6</mu1>
    <mu2>0.6</mu2>
    <self_collide>1</self_collide>
    <material>Gazebo/DarkGrey</material>
    <kp value="1000000.0"/>
    <kd value="100.0"/>
  </gazebo>
  <transmission name="LF_HAA_tran">
    <type>transmission_interface/SimpleTransmission</type>
    <joint name="LF_HAA">
      <hardwareInterface>hardware_interface/EffortJointInterface</hardwareInterface>
    </joint>
    <actuator name="LF_HAA_motor">
      <hardwareInterface>hardware_interface/EffortJointInterface</hardwareInterface>
      <mechanicalReduction>1</mechanicalReduction>
    </actuator>
  </transmission>
  <transmission name="LF_HFE_tran">
    <type>transmission_interface/SimpleTransmission</type>
    <joint name="LF_HFE">
      <hardwareInterface>hardware_interface/EffortJointInterface</hardwareInterface>
    </joint>
    <actuator name="LF_HFE_motor">
      <hardwareInterface>hardware_interface/EffortJointInterface</hardwareInterface>
      <mechanicalReduction>1</mechanicalReduction>
    </actuator>
  </transmission>
  <transmission name="LF_KFE_tran">
    <type>transmission_interface/SimpleTransmission</type>
    <joint name="LF_KFE">
      <hardwareInterface>hardware_interface/EffortJointInterface</hardwareInterface>
    </joint>
    <actuator name="LF_KFE_motor">
      <hardwareInterface>hardware_interface/EffortJointInterface</hardwareInterface>
      <mechanicalReduction>1</mechanicalReduction>
    </actuator>
  </transmission>
  <joint name="RH_HAA" type="revolute">
    <origin rpy="0 0 0" xyz="-0.1881 -0.04675 0"/>
    <parent link="base"/>
    <child link="RH_hip"/>
    <axis xyz="1 0 0"/>
    <dynamics damping="0.01" friction="0.2"/>
    <limit effort="23.7" lower="-0.863" upper="0.863" velocity="30.1"/>
  </joint>
  <link name="RH_hip">
    <visual>
      <origin rpy="3.141592653589793 3.141592653589793 0" xyz="0 0 0"/>
      <geometry>
        <mesh filename="package://Arm_URDF/meshes/go1/hip.dae" scale="1 1 1"/>
      </geometry>
      <material name="orange"/>
    </visual>
    <collision>
      <origin rpy="1.5707963267948966 0 0" xyz="0 0 0"/>
      <geometry>
        <cylinder length="0.04" radius="0.046"/>
      </geometry>
    </collision>
    <inertial>
      <origin rpy="0 0 0" xyz="0.005657 0.008752 -0.000102"/>
      <mass value="0.591"/>
      <inertia ixx="0.000334008405" ixy="-1.0826066e-05" ixz="-1.290732e-06" iyy="0.000619101213" iyz="-1.643194e-06" izz="0.00040057614"/>
    </inertial>
  </link>
  <joint name="RH_HFE" type="revolute">
    <origin rpy="0 0 0" xyz="0 -0.08 0"/>
    <parent link="RH_hip"/>
    <child link="RH_thigh"/>
    <axis xyz="0 1 0"/>
    <dynamics damping="0.01" friction="0.2"/>
    <limit effort="23.7" lower="-0.686" upper="4.501" velocity="30.1"/>
  </joint>
  <link name="RH_thigh">
    <visual>
      <origin rpy="0 0 0" xyz="0 0 0"/>
      <geometry>
        <mesh filename="package://Arm_URDF/meshes/go1/thigh_mirror.dae" scale="1 1 1"/>
      </geometry>
      <material name="orange"/>
    </visual>
    <collision>
      <origin rpy="0 1.6707963267948966 0" xyz="-0.015 0 -0.1065"/>
      <geometry>
        <box size="0.213 0.0245 0.034"/>
      </geometry>
    </collision>
    <collision>
      <origin rpy="1.5707963267948966 0 0" xyz="0 0.008 0"/>
      <geometry>
        <cylinder length="0.032" radius="0.041"/>
      </geometry>
    </collision>
    <inertial>
      <origin rpy="0 0 0" xyz="-0.003342 0.018054 -0.033451"/>
      <mass value="0.92"/>
      <inertia ixx="0.004431760472" ixy="-5.7496807e-05" ixz="-0.000218457134" iyy="0.004485671726" iyz="-0.000572001265" izz="0.000740309489"/>
    </inertial>
  </link>
  <joint name="RH_KFE" type="revolute">
    <origin rpy="0 0 0" xyz="0 0 -0.213"/>
    <parent link="RH_thigh"/>
    <child link="RH_calf"/>
    <axis xyz="0 1 0"/>
    <dynamics damping="0.01" friction="0.2"/>
    <limit effort="35.55" lower="-2.818" upper="-0.888" velocity="20.06"/>
  </joint>
  <link name="RH_calf">
    <visual>
      <origin rpy="0 0 0" xyz="0 0 0"/>
      <geometry>
        <mesh filename="package://Arm_URDF/meshes/go1/calf.dae" scale="1 1 1"/>
      </geometry>
      <material name="orange"/>
    </visual>
    <collision>
      <origin rpy="0 1.5707963267948966 0" xyz="0.0 0 -0.1065"/>
      <geometry>
        <box size="0.213 0.016 0.016"/>
      </geometry>
    </collision>
    <inertial>
      <origin rpy="0 0 0" xyz="0.006197 0.001408 -0.116695"/>
      <mass value="0.135862"/>
      <inertia ixx="0.001088793059" ixy="-2.55679e-07" ixz="7.117814e-06" iyy="0.001100428748" iyz="2.077264e-06" izz="2.4787446e-05"/>
    </inertial>
  </link>
  <joint name="RH_foot_fixed" type="fixed">
    <origin rpy="0 0 0" xyz="0 0 -0.213"/>
    <parent link="RH_calf"/>
    <child link="RH_FOOT"/>
  </joint>
  <link name="RH_FOOT">
    <visual>
      <origin rpy="0 0 0" xyz="0 0 0"/>
      <geometry>
        <sphere radius="0.01"/>
      </geometry>
      <material name="orange"/>
    </visual>
    <collision>
      <origin rpy="0 0 0" xyz="0 0 0"/>
      <geometry>
        <sphere radius="0.02"/>
      </geometry>
    </collision>
    <inertial>
      <mass value="0.06"/>
      <inertia ixx="9.600000000000001e-06" ixy="0.0" ixz="0.0" iyy="9.600000000000001e-06" iyz="0.0" izz="9.600000000000001e-06"/>
    </inertial>
  </link>
  <gazebo reference="RH_foot_fixed">
    <disableFixedJointLumping>true</disableFixedJointLumping>
  </gazebo>
  <gazebo reference="RH_hip">
    <mu1>0.2</mu1>
    <mu2>0.2</mu2>
    <material>Gazebo/DarkGrey</material>
  </gazebo>
  <gazebo reference="RH_thigh">
    <mu1>0.2</mu1>
    <mu2>0.2</mu2>
    <self_collide>0</self_collide>
    <material>Gazebo/DarkGrey</material>
    <kp value="1000000.0"/>
    <kd value="100.0"/>
  </gazebo>
  <gazebo reference="RH_calf">
    <mu1>0.6</mu1>
    <mu2>0.6</mu2>
    <self_collide>1</self_collide>
  </gazebo>
  <gazebo reference="RH_FOOT">
    <mu1>0.6</mu1>
    <mu2>0.6</mu2>
    <self_collide>1</self_collide>
    <material>Gazebo/DarkGrey</material>
    <kp value="1000000.0"/>
    <kd value="100.0"/>
  </gazebo>
  <transmission name="RH_HAA_tran">
    <type>transmission_interface/SimpleTransmission</type>
    <joint name="RH_HAA">
      <hardwareInterface>hardware_interface/EffortJointInterface</hardwareInterface>
    </joint>
    <actuator name="RH_HAA_motor">
      <hardwareInterface>hardware_interface/EffortJointInterface</hardwareInterface>
      <mechanicalReduction>1</mechanicalReduction>
    </actuator>
  </transmission>
  <transmission name="RH_HFE_tran">
    <type>transmission_interface/SimpleTransmission</type>
    <joint name="RH_HFE">
      <hardwareInterface>hardware_interface/EffortJointInterface</hardwareInterface>
    </joint>
    <actuator name="RH_HFE_motor">
      <hardwareInterface>hardware_interface/EffortJointInterface</hardwareInterface>
      <mechanicalReduction>1</mechanicalReduction>
    </actuator>
  </transmission>
  <transmission name="RH_KFE_tran">
    <type>transmission_interface/SimpleTransmission</type>
    <joint name="RH_KFE">
      <hardwareInterface>hardware_interface/EffortJointInterface</hardwareInterface>
    </joint>
    <actuator name="RH_KFE_motor">
      <hardwareInterface>hardware_interface/EffortJointInterface</hardwareInterface>
      <mechanicalReduction>1</mechanicalReduction>
    </actuator>
  </transmission>
  <joint name="LH_HAA" type="revolute">
    <origin rpy="0 0 0" xyz="-0.1881 0.04675 0"/>
    <parent link="base"/>
    <child link="LH_hip"/>
    <axis xyz="1 0 0"/>
    <dynamics damping="0.01" friction="0.2"/>
    <limit effort="23.7" lower="-0.863" upper="0.863" velocity="30.1"/>
  </joint>
  <link name="LH_hip">
    <visual>
      <origin rpy="0 3.141592653589793 0" xyz="0 0 0"/>
      <geometry>
        <mesh filename="package://Arm_URDF/meshes/go1/hip.dae" scale="1 1 1"/>
      </geometry>
      <material name="orange"/>
    </visual>
    <collision>
      <origin rpy="1.5707963267948966 0 0" xyz="0 0 0"/>
      <geometry>
        <cylinder length="0.04" radius="0.046"/>
      </geometry>
    </collision>
    <inertial>
      <origin rpy="0 0 0" xyz="0.005657 -0.008752 -0.000102"/>
      <mass value="0.591"/>
      <inertia ixx="0.000334008405" ixy="1.0826066e-05" ixz="-1.290732e-06" iyy="0.000619101213" iyz="1.643194e-06" izz="0.00040057614"/>
    </inertial>
  </link>
  <joint name="LH_HFE" type="revolute">
    <origin rpy="0 0 0" xyz="0 0.08 0"/>
    <parent link="LH_hip"/>
    <child link="LH_thigh"/>
    <axis xyz="0 1 0"/>
    <dynamics damping="0.01" friction="0.2"/>
    <limit effort="23.7" lower="-0.686" upper="4.501" velocity="30.1"/>
  </joint>
  <link name="LH_thigh">
    <visual>
      <origin rpy="0 0 0" xyz="0 0 0"/>
      <geometry>
        <mesh filename="package://Arm_URDF/meshes/go1/thigh.dae" scale="1 1 1"/>
      </geometry>
      <material name="orange"/>
    </visual>
    <collision>
      <origin rpy="0 1.6707963267948966 0" xyz="-0.015 0 -0.1065"/>
      <geometry>
        <box size="0.213 0.0245 0.034"/>
      </geometry>
    </collision>
    <collision>
      <origin rpy="1.5707963267948966 0 0" xyz="0 -0.008 0"/>
      <geometry>
        <cylinder length="0.032" radius="0.041"/>
      </geometry>
    </collision>
    <inertial>
      <origin rpy="0 0 0" xyz="-0.003342 -0.018054 -0.033451"/>
      <mass value="0.92"/>
      <inertia ixx="0.004431760472" ixy="5.7496807e-05" ixz="-0.000218457134" iyy="0.004485671726" iyz="0.000572001265" izz="0.000740309489"/>
    </inertial>
  </link>
  <joint name="LH_KFE" type="revolute">
    <origin rpy="0 0 0" xyz="0 0 -0.213"/>
    <parent link="LH_thigh"/>
    <child link="LH_calf"/>
    <axis xyz="0 1 0"/>
    <dynamics damping="0.01" friction="0.2"/>
    <limit effort="35.55" lower="-2.818" upper="-0.888" velocity="20.06"/>
  </joint>
  <link name="LH_calf">
    <visual>
      <origin rpy="0 0 0" xyz="0 0 0"/>
      <geometry>
        <mesh filename="package://Arm_URDF/meshes/go1/calf.dae" scale="1 1 1"/>
      </geometry>
      <material name="orange"/>
    </visual>
    <collision>
      <origin rpy="0 1.5707963267948966 0" xyz="0.0 0 -0.1065"/>
      <geometry>
        <box size="0.213 0.016 0.016"/>
      </geometry>
    </collision>
    <inertial>
      <origin rpy="0 0 0" xyz="0.006197 0.001408 -0.116695"/>
      <mass value="0.135862"/>
      <inertia ixx="0.001088793059" ixy="-2.55679e-07" ixz="7.117814e-06" iyy="0.001100428748" iyz="2.077264e-06" izz="2.4787446e-05"/>
    </inertial>
  </link>
  <joint name="LH_foot_fixed" type="fixed">
    <origin rpy="0 0 0" xyz="0 0 -0.213"/>
    <parent link="LH_calf"/>
    <child link="LH_FOOT"/>
  </joint>
  <link name="LH_FOOT">
    <visual>
      <origin rpy="0 0 0" xyz="0 0 0"/>
      <geometry>
        <sphere radius="0.01"/>
      </geometry>
      <material name="orange"/>
    </visual>
    <collision>
      <origin rpy="0 0 0" xyz="0 0 0"/>
      <geometry>
        <sphere radius="0.02"/>
      </geometry>
    </collision>
    <inertial>
      <mass value="0.06"/>
      <inertia ixx="9.600000000000001e-06" ixy="0.0" ixz="0.0" iyy="9.600000000000001e-06" iyz="0.0" izz="9.600000000000001e-06"/>
    </inertial>
  </link>
  <gazebo reference="LH_foot_fixed">
    <disableFixedJointLumping>true</disableFixedJointLumping>
  </gazebo>
  <gazebo reference="LH_hip">
    <mu1>0.2</mu1>
    <mu2>0.2</mu2>
    <material>Gazebo/DarkGrey</material>
  </gazebo>
  <gazebo reference="LH_thigh">
    <mu1>0.2</mu1>
    <mu2>0.2</mu2>
    <self_collide>0</self_collide>
    <material>Gazebo/DarkGrey</material>
    <kp value="1000000.0"/>
    <kd value="100.0"/>
  </gazebo>
  <gazebo reference="LH_calf">
    <mu1>0.6</mu1>
    <mu2>0.6</mu2>
    <self_collide>1</self_collide>
  </gazebo>
  <gazebo reference="LH_FOOT">
    <mu1>0.6</mu1>
    <mu2>0.6</mu2>
    <self_collide>1</self_collide>
    <material>Gazebo/DarkGrey</material>
    <kp value="1000000.0"/>
    <kd value="100.0"/>
  </gazebo>
  <transmission name="LH_HAA_tran">
    <type>transmission_interface/SimpleTransmission</type>
    <joint name="LH_HAA">
      <hardwareInterface>hardware_interface/EffortJointInterface</hardwareInterface>
    </joint>
    <actuator name="LH_HAA_motor">
      <hardwareInterface>hardware_interface/EffortJointInterface</hardwareInterface>
      <mechanicalReduction>1</mechanicalReduction>
    </actuator>
  </transmission>
  <transmission name="LH_HFE_tran">
    <type>transmission_interface/SimpleTransmission</type>
    <joint name="LH_HFE">
      <hardwareInterface>hardware_interface/EffortJointInterface</hardwareInterface>
    </joint>
    <actuator name="LH_HFE_motor">
      <hardwareInterface>hardware_interface/EffortJointInterface</hardwareInterface>
      <mechanicalReduction>1</mechanicalReduction>
    </actuator>
  </transmission>
  <transmission name="LH_KFE_tran">
    <type>transmission_interface/SimpleTransmission</type>
    <joint name="LH_KFE">
      <hardwareInterface>hardware_interface/EffortJointInterface</hardwareInterface>
    </joint>
    <actuator name="LH_KFE_motor">
      <hardwareInterface>hardware_interface/EffortJointInterface</hardwareInterface>
      <mechanicalReduction>1</mechanicalReduction>
    </actuator>
  </transmission>

  <!-- Arm -->
  <link name="arm_base">
    <visual>
    <origin xyz="-0.043000000000000093703 -0.056249572745411466346 0.053674572697836049617" rpy="1.570796326794896558 6.9388939039074071039e-18 -2.0296264668928948688e-16" />
    <geometry>
    <mesh filename="package://Arm_URDF/meshes/arm/batterycover.stl"/>
    </geometry>
    <material name="batterycover_material">
    <color rgba="0.79607843137254896693 0.82352941176470584317 0.9372549019607843146 1.0"/>
    </material>
    </visual>
    <collision>
    <origin xyz="-0.043000000000000093703 -0.056249572745411466346 0.053674572697836049617" rpy="1.570796326794896558 6.9388939039074071039e-18 -2.0296264668928948688e-16" />
    <geometry>
    <mesh filename="package://Arm_URDF/meshes/arm/batterycover.stl"/>
    </geometry>
    </collision>
    <visual>
    <origin xyz="0.027999999999999969358 0.045620425736449282672 -0.0078254274213730105197" rpy="-1.570796326794896558 -0 -1.570796326794896558" />
    <geometry>
    <mesh filename="package://Arm_URDF/meshes/arm/bar.stl"/>
    </geometry>
    <material name="bar_material">
    <color rgba="0.62745098039215685404 0.62745098039215685404 0.62745098039215685404 1.0"/>
    </material>
    </visual>
    <collision>
    <origin xyz="0.027999999999999969358 0.045620425736449282672 -0.0078254274213730105197" rpy="-1.570796326794896558 -0 -1.570796326794896558" />
    <geometry>
    <mesh filename="package://Arm_URDF/meshes/arm/bar.stl"/>
    </geometry>
    </collision>
    <visual>
    <origin xyz="-0.045499999999999984901 0.18587042725458807757 0.00017457269783627965554" rpy="-1.570796326794896558 -0 -1.570796326794896558" />
    <geometry>
    <mesh filename="package://Arm_URDF/meshes/arm/nuc_enclosure_right_v8.step.stl"/>
    </geometry>
    <material name="nuc_enclosure_right_v8.step_material">
    <color rgba="0.62745098039215685404 0.62745098039215685404 0.62745098039215685404 1.0"/>
    </material>
    </visual>
    <collision>
    <origin xyz="-0.045499999999999984901 0.18587042725458807757 0.00017457269783627965554" rpy="-1.570796326794896558 -0 -1.570796326794896558" />
    <geometry>
    <mesh filename="package://Arm_URDF/meshes/arm/nuc_enclosure_right_v8.step.stl"/>
    </geometry>
    </collision>
    <visual>
    <origin xyz="-0.029000000000002121303 0.050370427254587735177 0.059174572697836602675" rpy="1.570796326794896558 9.0105057071027178548e-17 1.570796326794896558" />
    <geometry>
    <mesh filename="package://Arm_URDF/meshes/arm/cap.stl"/>
    </geometry>
    <material name="cap_material">
    <color rgba="0.62745098039215685404 0.62745098039215685404 0.62745098039215685404 1.0"/>
    </material>
    </visual>
    <collision>
    <origin xyz="-0.029000000000002121303 0.050370427254587735177 0.059174572697836602675" rpy="1.570796326794896558 9.0105057071027178548e-17 1.570796326794896558" />
    <geometry>
    <mesh filename="package://Arm_URDF/meshes/arm/cap.stl"/>
    </geometry>
    </collision>
    <visual>
    <origin xyz="-9.0000000000006741274e-05 -0.001039572745412595256 0.037174572697836277824" rpy="-1.570796326794896558 -0 0" />
    <geometry>
    <mesh filename="package://Arm_URDF/meshes/arm/motor.stl"/>
    </geometry>
    <material name="motor_material">
    <color rgba="1 1 1 1.0"/>
    </material>
    </visual>
    <collision>
    <origin xyz="-9.0000000000006741274e-05 -0.001039572745412595256 0.037174572697836277824" rpy="-1.570796326794896558 -0 0" />
    <geometry>
    <mesh filename="package://Arm_URDF/meshes/arm/motor.stl"/>
    </geometry>
    </collision>
    <visual>
    <origin xyz="0.045500000000000005718 0.037870427254587731014 0.00017457269783625623677" rpy="-1.570796326794896558 -2.2204460492410355836e-16 1.57079632679489678" />
    <geometry>
    <mesh filename="package://Arm_URDF/meshes/arm/nuc_enclosure_left_v27.step.stl"/>
    </geometry>
    <material name="nuc_enclosure_left_v27.step_material">
    <color rgba="0.62745098039215685404 0.62745098039215685404 0.62745098039215685404 1.0"/>
    </material>
    </visual>
    <collision>
    <origin xyz="0.045500000000000005718 0.037870427254587731014 0.00017457269783625623677" rpy="-1.570796326794896558 -2.2204460492410355836e-16 1.57079632679489678" />
    <geometry>
    <mesh filename="package://Arm_URDF/meshes/arm/nuc_enclosure_left_v27.step.stl"/>
    </geometry>
    </collision>
    <visual>
    <origin xyz="0 -0.001129572745412591589 0.00017457269783627965554" rpy="0 -0 0" />
    <geometry>
    <mesh filename="package://Arm_URDF/meshes/arm/base.stl"/>
    </geometry>
    <material name="base_material">
    <color rgba="1 1 1 1.0"/>
    </material>
    </visual>
    <collision>
    <origin xyz="0 -0.001129572745412591589 0.00017457269783627965554" rpy="0 -0 0" />
    <geometry>
    <mesh filename="package://Arm_URDF/meshes/arm/base.stl"/>
    </geometry>
    </collision>
    <visual>
    <origin xyz="-0.0030000000000000581757 0.11587042725458805703 0.0041745726978362797388" rpy="0 -0 -1.2325951644077898923e-32" />
    <geometry>
    <mesh filename="package://Arm_URDF/meshes/arm/nuc.stl"/>
    </geometry>
    <material name="nuc_material">
    <color rgba="0.61568627450980395466 0.81176470588235294379 0.92941176470588238168 1.0"/>
    </material>
    </visual>
    <collision>
    <origin xyz="-0.0030000000000000581757 0.11587042725458805703 0.0041745726978362797388" rpy="0 -0 -1.2325951644077898923e-32" />
    <geometry>
    <mesh filename="package://Arm_URDF/meshes/arm/nuc.stl"/>
    </geometry>
    </collision>
    <visual>
    <origin xyz="-0.063000000000000000444 0.045620425736449157772 -0.0078254274213730122545" rpy="-1.570796326794896558 -0 -1.570796326794896558" />
    <geometry>
    <mesh filename="package://Arm_URDF/meshes/arm/bar.stl"/>
    </geometry>
    <material name="bar_material">
    <color rgba="0.62745098039215685404 0.62745098039215685404 0.62745098039215685404 1.0"/>
    </material>
    </visual>
    <collision>
    <origin xyz="-0.063000000000000000444 0.045620425736449157772 -0.0078254274213730122545" rpy="-1.570796326794896558 -0 -1.570796326794896558" />
    <geometry>
    <mesh filename="package://Arm_URDF/meshes/arm/bar.stl"/>
    </geometry>
    </collision>
    <visual>
    <origin xyz="-0.040500000000000015155 -0.056249572745412590447 0.053674572697836375745" rpy="1.570796326794896558 1.5919291637703030189e-31 1.3010426069826006369e-16" />
    <geometry>
    <mesh filename="package://Arm_URDF/meshes/arm/batterybox.stl"/>
    </geometry>
    <material name="batterybox_material">
    <color rgba="0.79607843137254896693 0.82352941176470584317 0.9372549019607843146 1.0"/>
    </material>
    </visual>
    <collision>
    <origin xyz="-0.040500000000000015155 -0.056249572745412590447 0.053674572697836375745" rpy="1.570796326794896558 1.5919291637703030189e-31 1.3010426069826006369e-16" />
    <geometry>
    <mesh filename="package://Arm_URDF/meshes/arm/batterybox.stl"/>
    </geometry>
    </collision>
    <visual>
    <origin xyz="0 -0.001129572745412591589 0.078174572697836286483" rpy="0 -0 0" />
    <geometry>
    <mesh filename="package://Arm_URDF/meshes/arm/base2.stl"/>
    </geometry>
    <material name="base2_material">
    <color rgba="1 1 1 1.0"/>
    </material>
    </visual>
    <collision>
    <origin xyz="0 -0.001129572745412591589 0.078174572697836286483" rpy="0 -0 0" />
    <geometry>
    <mesh filename="package://Arm_URDF/meshes/arm/base2.stl"/>
    </geometry>
    </collision>
    <inertial>
    <origin xyz="-0.0010344577161941546743 0.04181890992252584871 0.029898059563253923804" rpy="0 0 0"/>
    <mass value="2.728488216480799089" />
    <inertia ixx="0.02706774372853133076" ixy="0.00054067252642245040677"  ixz="2.8567880911383165094e-05" iyy="0.0038152470185468614385" iyz="0.00054819753264507132921" izz="0.028383963686429720258" />
    </inertial>
  </link>

  <link name="link1">
    <visual>
    <origin xyz="-0.0054332708436385518391 -1.7997756063259373605e-17 -0.033000000000000001554" rpy="3.141592653589793116 -9.8090892502737194965e-45 1.267861666945625271e-17" />
    <geometry>
    <mesh filename="package://Arm_URDF/meshes/arm/link1.stl"/>
    </geometry>
    <material name="link1_material">
    <color rgba="1 1 1 1.0"/>
    </material>
    </visual>
    <collision>
    <origin xyz="-0.0054332708436385518391 -1.7997756063259373605e-17 -0.033000000000000001554" rpy="3.141592653589793116 -9.8090892502737194965e-45 1.267861666945625271e-17" />
    <geometry>
    <mesh filename="package://Arm_URDF/meshes/arm/link1.stl"/>
    </geometry>
    </collision>
    <visual>
    <origin xyz="-0.0054332708436385518391 -1.7997756063259373605e-17 -0.033000000000000001554" rpy="-3.141592653589793116 -1.570796326794896558 0" />
    <geometry>
    <mesh filename="package://Arm_URDF/meshes/arm/base2.stl"/>
    </geometry>
    <material name="base2_material">
    <color rgba="1 1 1 1.0"/>
    </material>
    </visual>
    <collision>
    <origin xyz="-0.0054332708436385518391 -1.7997756063259373605e-17 -0.033000000000000001554" rpy="-3.141592653589793116 -1.570796326794896558 0" />
    <geometry>
    <mesh filename="package://Arm_URDF/meshes/arm/base2.stl"/>
    </geometry>
    </collision>
    <visual>
    <origin xyz="-0.046433270843638324576 8.9999999999992863486e-05 -0.033089999999999925029" rpy="1.570796326794896558 -1.5707963267948961139 0" />
    <geometry>
    <mesh filename="package://Arm_URDF/meshes/arm/motor.stl"/>
    </geometry>
    <material name="motor_material">
    <color rgba="1 1 1 1.0"/>
    </material>
    </visual>
    <collision>
    <origin xyz="-0.046433270843638324576 8.9999999999992863486e-05 -0.033089999999999925029" rpy="1.570796326794896558 -1.5707963267948961139 0" />
    <geometry>
    <mesh filename="package://Arm_URDF/meshes/arm/motor.stl"/>
    </geometry>
    </collision>
    <inertial>
    <origin xyz="-0.041242122456885535464 9.5447388145449493248e-05 -0.030973541753897184531" rpy="0 0 0"/>
    <mass value="0.58371184536850717617" />
    <inertia ixx="0.00019245383353722509095" ixy="2.1656015044083137864e-07"  ixz="-1.212208052300071926e-05" iyy="0.00041195380001483834298" iyz="1.1823486784021973871e-07" izz="0.00037713570669470287879" />
    </inertial>
  </link>

  <link name="link2">
    <visual>
    <origin xyz="-0.20499999999999776734 -6.6613381477509392425e-16 0.059999999999999720224" rpy="-1.7029276923339265031e-15 -1.570796326794896558 0" />
    <geometry>
    <mesh filename="package://Arm_URDF/meshes/arm/link2.2.stl"/>
    </geometry>
    <material name="link2.2_material">
    <color rgba="1 1 1 1.0"/>
    </material>
    </visual>
    <collision>
    <origin xyz="-0.20499999999999776734 -6.6613381477509392425e-16 0.059999999999999720224" rpy="-1.7029276923339265031e-15 -1.570796326794896558 0" />
    <geometry>
    <mesh filename="package://Arm_URDF/meshes/arm/link2.2.stl"/>
    </geometry>
    </collision>
    <visual>
    <origin xyz="-0.20499999999999782285 -5.9674487573602164048e-16 0.059999999999999706346" rpy="1.778867441181035444e-17 4.8251088930317348765e-16 3.1415926535897926719" />
    <geometry>
    <mesh filename="package://Arm_URDF/meshes/arm/base2.stl"/>
    </geometry>
    <material name="base2_material">
    <color rgba="1 1 1 1.0"/>
    </material>
    </visual>
    <collision>
    <origin xyz="-0.20499999999999782285 -5.9674487573602164048e-16 0.059999999999999706346" rpy="1.778867441181035444e-17 4.8251088930317348765e-16 3.1415926535897926719" />
    <geometry>
    <mesh filename="package://Arm_URDF/meshes/arm/base2.stl"/>
    </geometry>
    </collision>
    <visual>
    <origin xyz="0 0 0.020000000000000000416" rpy="1.570796326794896558 1.570796326794896558 0" />
    <geometry>
    <mesh filename="package://Arm_URDF/meshes/arm/link2.stl"/>
    </geometry>
    <material name="link2_material">
    <color rgba="1 1 1 1.0"/>
    </material>
    </visual>
    <collision>
    <origin xyz="0 0 0.020000000000000000416" rpy="1.570796326794896558 1.570796326794896558 0" />
    <geometry>
    <mesh filename="package://Arm_URDF/meshes/arm/link2.stl"/>
    </geometry>
    </collision>
    <visual>
    <origin xyz="-0.20508999999999941166 8.9999999999298974096e-05 0.019000000000000412392" rpy="-1.570796326794896558 9.5727299502079627247e-16 -1.08214256620902617e-15" />
    <geometry>
    <mesh filename="package://Arm_URDF/meshes/arm/motor.stl"/>
    </geometry>
    <material name="motor_material">
    <color rgba="1 1 1 1.0"/>
    </material>
    </visual>
    <collision>
    <origin xyz="-0.20508999999999941166 8.9999999999298974096e-05 0.019000000000000412392" rpy="-1.570796326794896558 9.5727299502079627247e-16 -1.08214256620902617e-15" />
    <geometry>
    <mesh filename="package://Arm_URDF/meshes/arm/motor.stl"/>
    </geometry>
    </collision>
    <inertial>
    <origin xyz="-0.18369256495623187408 5.1287889447513036203e-05 0.01467330229163361921" rpy="0 0 0"/>
    <mass value="0.69558895030050260644" />
    <inertia ixx="0.00057902308488614251045" ixy="8.3152475479661448625e-07"  ixz="0.00045703634575853965783" iyy="0.0024076671898047912954" iyz="-5.0553322379110441339e-07" izz="0.0020098405261636405859" />
    </inertial>
  </link>

  <link name="link3">
    <visual>
    <origin xyz="-0.14755927857215847543 -0.0030709617015239887294 0.034999999999999531486" rpy="-1.570796326794901443 7.8815869593862586232e-16 1.7713591602216023357" />
    <geometry>
    <mesh filename="package://Arm_URDF/meshes/arm/gripper_3.stl"/>
    </geometry>
    <material name="gripper_3_material">
    <color rgba="0 0.50196078431372548323 1 1.0"/>
    </material>
    </visual>
    <collision>
    <origin xyz="-0.14755927857215847543 -0.0030709617015239887294 0.034999999999999531486" rpy="-1.570796326794901443 7.8815869593862586232e-16 1.7713591602216023357" />
    <geometry>
    <mesh filename="package://Arm_URDF/meshes/arm/gripper_3.stl"/>
    </geometry>
    </collision>
    <visual>
    <origin xyz="-0.095067017584915369799 0.0037828239434247734607 0.008215004668317753278" rpy="3.5664695208912036138e-16 -1.570796326794896558 0" />
    <geometry>
    <mesh filename="package://Arm_URDF/meshes/arm/part_2.stl"/>
    </geometry>
    <material name="part_2_material">
    <color rgba="0.79607843137254896693 0.82352941176470584317 0.9372549019607843146 1.0"/>
    </material>
    </visual>
    <collision>
    <origin xyz="-0.095067017584915369799 0.0037828239434247734607 0.008215004668317753278" rpy="3.5664695208912036138e-16 -1.570796326794896558 0" />
    <geometry>
    <mesh filename="package://Arm_URDF/meshes/arm/part_2.stl"/>
    </geometry>
    </collision>
    <visual>
    <origin xyz="-0.11574999999999993627 0.00092468640208276386971 0.019999999999999566735" rpy="4.0236093262708227392e-17 -4.9438733272218117758e-17 2.0144807537012205006e-16" />
    <geometry>
    <mesh filename="package://Arm_URDF/meshes/arm/servo.stl"/>
    </geometry>
    <material name="servo_material">
    <color rgba="0.61568627450980395466 0.81176470588235294379 0.92941176470588238168 1.0"/>
    </material>
    </visual>
    <collision>
    <origin xyz="-0.11574999999999993627 0.00092468640208276386971 0.019999999999999566735" rpy="4.0236093262708227392e-17 -4.9438733272218117758e-17 2.0144807537012205006e-16" />
    <geometry>
    <mesh filename="package://Arm_URDF/meshes/arm/servo.stl"/>
    </geometry>
    </collision>
    <visual>
    <origin xyz="-0.13174999999999989497 -0.0084999999999998965272 0.037499999999999616973" rpy="-0.20056283342669889436 1.570796326794896558 0" />
    <geometry>
    <mesh filename="package://Arm_URDF/meshes/arm/gripper_1.stl"/>
    </geometry>
    <material name="gripper_1_material">
    <color rgba="0.89411764705882357251 0.91372549019607840481 0.92941176470588238168 1.0"/>
    </material>
    </visual>
    <collision>
    <origin xyz="-0.13174999999999989497 -0.0084999999999998965272 0.037499999999999616973" rpy="-0.20056283342669889436 1.570796326794896558 0" />
    <geometry>
    <mesh filename="package://Arm_URDF/meshes/arm/gripper_1.stl"/>
    </geometry>
    </collision>
    <visual>
    <origin xyz="-2.7755575615628913511e-17 -5.5511151231257827021e-17 0.020000000000000010825" rpy="1.570796326794896558 1.570796326794896558 0" />
    <geometry>
    <mesh filename="package://Arm_URDF/meshes/arm/link3.stl"/>
    </geometry>
    <material name="link3_material">
    <color rgba="1 1 1 1.0"/>
    </material>
    </visual>
    <collision>
    <origin xyz="-2.7755575615628913511e-17 -5.5511151231257827021e-17 0.020000000000000010825" rpy="1.570796326794896558 1.570796326794896558 0" />
    <geometry>
    <mesh filename="package://Arm_URDF/meshes/arm/link3.stl"/>
    </geometry>
    </collision>
    <visual>
    <origin xyz="-0.14669465341390486302 0.0010123381382037832665 0.035000000000000003331" rpy="1.5707963267948950037 -7.6463365347586373083e-16 -1.6376814851098608905" />
    <geometry>
    <mesh filename="package://Arm_URDF/meshes/arm/gripper_3.stl"/>
    </geometry>
    <material name="gripper_3_material">
    <color rgba="0 0.50196078431372548323 1 1.0"/>
    </material>
    </visual>
    <collision>
    <origin xyz="-0.14669465341390486302 0.0010123381382037832665 0.035000000000000003331" rpy="1.5707963267948950037 -7.6463365347586373083e-16 -1.6376814851098608905" />
    <geometry>
    <mesh filename="package://Arm_URDF/meshes/arm/gripper_3.stl"/>
    </geometry>
    </collision>
    <visual>
    <origin xyz="-0.095067017584915369799 0.0037828239434247734607 0.008215004668317753278" rpy="3.5664695208912036138e-16 -1.570796326794896558 0" />
    <geometry>
    <mesh filename="package://Arm_URDF/meshes/arm/part_1.stl"/>
    </geometry>
    <material name="part_1_material">
    <color rgba="0.79607843137254896693 0.82352941176470584317 0.9372549019607843146 1.0"/>
    </material>
    </visual>
    <collision>
    <origin xyz="-0.095067017584915369799 0.0037828239434247734607 0.008215004668317753278" rpy="3.5664695208912036138e-16 -1.570796326794896558 0" />
    <geometry>
    <mesh filename="package://Arm_URDF/meshes/arm/part_1.stl"/>
    </geometry>
    </collision>
    <visual>
    <origin xyz="-0.13174999999999989497 0.0084999999999998410161 0.037500000000000054123" rpy="0.066885158314967024795 1.570796326794896558 0" />
    <geometry>
    <mesh filename="package://Arm_URDF/meshes/arm/gripper_2.stl"/>
    </geometry>
    <material name="gripper_2_material">
    <color rgba="0.89411764705882357251 0.91372549019607840481 0.92941176470588238168 1.0"/>
    </material>
    </visual>
    <collision>
    <origin xyz="-0.13174999999999989497 0.0084999999999998410161 0.037500000000000054123" rpy="0.066885158314967024795 1.570796326794896558 0" />
    <geometry>
    <mesh filename="package://Arm_URDF/meshes/arm/gripper_2.stl"/>
    </geometry>
    </collision>
    <visual>
    <origin xyz="-0.1157499999999999224 0 0.037499999999999561462" rpy="-1.57079632679489678 -2.1571113117678167993e-16 1.5707963267948956698" />
    <geometry>
    <mesh filename="package://Arm_URDF/meshes/arm/gripper_4.stl"/>
    </geometry>
    <material name="gripper_4_material">
    <color rgba="0.89411764705882357251 0.91372549019607840481 0.92941176470588238168 1.0"/>
    </material>
    </visual>
    <collision>
    <origin xyz="-0.1157499999999999224 0 0.037499999999999561462" rpy="-1.57079632679489678 -2.1571113117678167993e-16 1.5707963267948956698" />
    <geometry>
    <mesh filename="package://Arm_URDF/meshes/arm/gripper_4.stl"/>
    </geometry>
    </collision>
    <inertial>
    <origin xyz="-0.089483000114599725583 -0.00038577658413896105238 0.0018940659154347233659" rpy="0 0 0"/>
    <mass value="0.13213715938135658923" />
    <inertia ixx="0.00010975026839934459038" ixy="-7.3563565811300834379e-06"  ixz="0.00013977189346253430439" iyy="0.00056140953791821920915" iyz="1.7061822566271839312e-06" izz="0.00049411105582780785739" />
    </inertial>
  </link>

  <joint name="j3" type="fixed">
    <origin xyz="-0.20509002189797051474 -1.4672502470558512755e-05 0.090080000000002602434" rpy="-3.1415926535897922278 -9.3305013695572322979e-15 1.7546092432393536331" />
    <parent link="link2" />
    <child link="link3" />
    <axis xyz="0 0 1"/>
    <limit effort="1" velocity="20" />
    <joint_properties friction="0.0"/>
  </joint>

  <joint name="j2" type="fixed">
    <origin xyz="0.024646729156363667707 0.00019467250247003466471 -0.033090021897969917886" rpy="-1.570796326794896558 -0.95603848300716276487 1.5707963267949527353" />
    <parent link="link1" />
    <child link="link2" />
    <axis xyz="0 0 1"/>
    <limit effort="1" velocity="20" />
    <joint_properties friction="0.0"/>
  </joint>

  <joint name="j1" type="fixed">
    <origin xyz="-9.0021897970908593134e-05 -0.0011442452478826114701 0.10063457269783629422" rpy="3.141592653589793116 8.692399673602098605e-30 0.09066580704768881227" />
    <parent link="arm_base" />
    <child link="link1" />
    <axis xyz="0 0 1"/>
    <limit effort="1" velocity="20" />
    <joint_properties friction="0.0"/>
  </joint>

  <joint name="base_to_arm" type="fixed">
    <origin xyz="-0.04 0 0.065" rpy="0 0 -1.5708" />
    <parent link="base" />
    <child link="arm_base" />
  </joint>
</robot>
